<mujoco model="table_scene">
  <compiler angle="radian" meshdir="assets/"/>

  <option timestep="0.001" impratio="10" density="1.2" integrator="implicitfast" cone="elliptic">
    <flag multiccd="enable"/>
  </option>

  <visual>
    <global azimuth="120" elevation="-20"/>
    <quality shadowsize="8192"/>
    <headlight ambient="0.3 0.3 0.3" diffuse="0.5 0.5 0.5" specular="0 0 0"/>
    <scale forcewidth="0.025" contactwidth="0.05" contactheight="0.025" com="0.2" jointwidth="0.05" actuatorwidth="0.1" framelength="0.5" framewidth="0.02" constraint="0.02"/>
    <rgba haze="0.15 0.25 0.35 1"/>
  </visual>

  <statistic extent="1" center="0 0 0.1"/>

  <default>
    <default class="a1">
      <general biastype="affine" gainprm="1000" biasprm="0 -1000 -100"/>
      <default class="visual">
        <geom type="mesh" contype="0" conaffinity="0" group="1" rgba="0.79216 0.81961 0.93333 1"/>
        <site size="0.02 0.02 0.02" group="1" type="box" rgba="0.8 0.6 0.1 0.5"/>
      </default>
      <default class="collision">
        <geom type="mesh" group="3" rgba="0.79216 0.81961 0.93333 0.5"/>
        <default class="collision_finger">
          <geom condim="6" priority="1" friction="1 0.005 0.001" solref="0.01"/>
        </default>
      </default>
    </default>
  </default>

  <asset>
    <texture type="skybox" builtin="gradient" rgb1="0.3 0.5 0.7" rgb2="0 0 0" width="512" height="3072"/>
    <texture type="2d" name="groundplane" builtin="checker" mark="edge" rgb1="0.2 0.3 0.4" rgb2="0.1 0.2 0.3" markrgb="0.8 0.8 0.8" width="300" height="300"/>
    <texture type="2d" name="wood_tex" file="assets/wood.png"/>
    <material name="groundplane" texture="groundplane" texuniform="true" texrepeat="5 5" reflectance="0.2"/>
    <material name="wood" texture="wood_tex"/>
    <mesh name="base_link" file="base_link.STL"/>
    <mesh name="arm_seg1" file="arm_seg1.STL"/>
    <mesh name="arm_seg2" file="arm_seg2.STL"/>
    <mesh name="arm_seg3" file="arm_seg3.STL"/>
    <mesh name="arm_seg4" file="arm_seg4.STL"/>
    <mesh name="arm_seg5" file="arm_seg5.STL"/>
    <mesh name="arm_seg6" file="arm_seg6.STL"/>
    <mesh name="gripper1" file="gripper1.STL"/>
    <mesh name="gripper2" file="gripper2.STL"/>
    <mesh name="finger_touch" file="finger_touch.STL" scale="1 2 1"/>
  </asset>

  <worldbody>
    <geom name="floor" size="0 0 0.05" type="plane" material="groundplane"/>
    <light pos="0 0 2" dir="0 0 -1" directional="true"/>
    <body name="base_link" pos="0.1 0 0.21">
      <inertial pos="-0.00056269 -4.1498e-06 0.038934" quat="0.0068651 0.761577 -0.00462291 0.648022" mass="1" diaginertia="0.00118192 0.0010647 0.00105648"/>
      <geom class="visual" mesh="base_link"/>
      <geom class="collision" mesh="base_link"/>
      <body name="arm_seg1" pos="-0.0011147 0 0.0892" quat="-3.67321e-06 0 0 1">
        <inertial pos="-1.4403e-06 -0.00074041 0.056573" quat="0.707084 0.00122867 -0.00107609 0.707127" mass="1.391" diaginertia="0.000708573 0.00058101 0.000445827"/>
        <joint name="arm_joint1" pos="0 0 0" axis="0 0 1" range="-2.8798 2.8798" actuatorfrcrange="-40 40"/>
        <geom class="visual" mesh="arm_seg1"/>
        <geom class="collision" mesh="arm_seg1"/>
        <body name="arm_seg2" pos="0 -4e-05 0.0615" quat="0.707105 0.707108 0 0">
          <inertial pos="0.23622 0.016356 9.154e-05" quat="0.484393 0.48518 0.524693 0.504639" mass="1.3" diaginertia="0.00761886 0.00757469 0.000578276"/>
          <joint name="arm_joint2" pos="0 0 0" axis="0 0 1" range="0 3.1415" actuatorfrcrange="-40 40"/>
          <geom class="visual" mesh="arm_seg2"/>
          <geom class="collision" mesh="arm_seg2"/>
          <body name="arm_seg3" pos="0.34928 0.02 0" quat="0.707105 0 0 0.707108">
            <inertial pos="0.054443 0.045347 0.00042807" quat="0.595278 0.471808 -0.522016 0.387995" mass="0.818" diaginertia="0.00149749 0.00144877 0.00053598"/>
            <joint name="arm_joint3" pos="0 0 0" axis="0 0 1" range="-3.3161 0" actuatorfrcrange="-27 27"/>
            <geom class="visual" mesh="arm_seg3"/>
            <geom class="collision" mesh="arm_seg3"/>
            <body name="arm_seg4" pos="0.07 -0.00395 -4e-05" quat="0.499998 -0.5 0.5 0.500002">
              <inertial pos="7.6256e-07 -0.0021448 0.27415" quat="0.70651 0.0169198 -0.0168252 0.707301" mass="0.816" diaginertia="0.000101779 9.7042e-05 8.44616e-05"/>
              <joint name="arm_joint4" pos="0 0 0" axis="0 0 1" range="-2.8798 2.8798" actuatorfrcrange="-7 7"/>
              <geom class="visual" rgba="1 1 1 1" mesh="arm_seg4"/>
              <geom class="collision" rgba="1 1 1 1" mesh="arm_seg4"/>
              <body name="arm_seg5" pos="0 0 0.2776" quat="-2.59734e-06 2.59735e-06 -0.707108 0.707105">
                <inertial pos="-3.9997e-06 -0.05431 0.0034482" quat="0.477398 0.87868 0.00338218 -0.000840949" mass="0.801" diaginertia="0.00011332 0.000109027 7.34689e-05"/>
                <joint name="arm_joint5" pos="0 0 0" axis="0 0 1" range="-1.6581 1.6581" actuatorfrcrange="-7 7"/>
                <geom class="visual" rgba="1 1 1 1" mesh="arm_seg5"/>
                <geom class="collision" rgba="1 1 1 1" mesh="arm_seg5"/>
                <body name="arm_seg6" pos="0 -0.1575 -0.00023266" quat="0.707105 0.707108 0 0">
                  <inertial pos="2.406e-06 -9.4582e-08 -0.038796" quat="1 -8.0778e-06 -0.000185306 8.09142e-05" mass="0.465" diaginertia="0.00011445 0.00011239 7.4519e-05"/>
                  <joint name="arm_joint6" pos="0 0 0" axis="0 0 1" range="-2.8798 2.8798" actuatorfrcrange="-7 7"/>
                  <geom class="visual" mesh="arm_seg6"/>
                  <geom class="collision" mesh="arm_seg6"/>
                  <site name="eef" class="visual" pos="0 0 0"/>
                  <camera name="wrist_cam" pos="0.05 0 0" quat="0.142175 0.692666 0.692666 0.142175"/>
                  <body name="gripper1" pos="0.014 -0.011914 0.003125" quat="-0.499979 0.500023 0.499977 0.500021">
                    <inertial pos="0.022575 -0.01276 0.015787" quat="0.0822694 0.728978 0.0705012 0.675909" mass="0.057" diaginertia="5.31459e-06 4.69942e-06 1.74659e-06"/>
                    <joint name="gripper1_axis" pos="0 0 0" axis="0 0 1" type="slide" range="0 0.03" actuatorfrcrange="-200 200"/>
                    <geom class="visual" mesh="gripper1"/>
                    <geom class="collision_finger" pos="0.02 -0.014 0.04" quat="0.707105 0.707108 0 0" rgba="0.2 0.2 0.8 1" mesh="finger_touch"/>
                  </body>
                  <body name="gripper2" pos="-0.014 0.011914 0.003125" quat="0.500025 0.499977 -0.500023 0.499975">
                    <inertial pos="0.022575 -0.01276 0.015787" quat="0.0822694 0.728978 0.0705012 0.675909" mass="0.057" diaginertia="5.31459e-06 4.69942e-06 1.74659e-06"/>
                    <joint name="gripper2_axis" pos="0 0 0" axis="0 0 1" type="slide" range="0 0.03" actuatorfrcrange="-200 200"/>
                    <geom class="visual" mesh="gripper2"/>
                    <geom class="collision_finger" pos="0.02 -0.014 0.04" quat="0.707105 0.707108 0 0" rgba="0.2 0.2 0.8 1" mesh="finger_touch"/>
                  </body>
                </body>
              </body>
            </body>
          </body>
        </body>
      </body>
    </body>
    <body name="table" pos="0.5 0 0.2">
      <geom size="0.5 0.5 0.01" type="box" material="wood"/>
      <camera name="table_cam" target="table" pos="-0.7 -0.7 0.2" mode="targetbody"/>
    </body>
    <body name="bin" pos="0.5 0 0.3">
      <joint type="free" limited="false" actuatorfrclimited="false"/>
      <geom size="0.02 0.03" type="cylinder" mass="0.05" rgba="0.884085 0.494375 0.336035 1"/>
    </body>
    <body name="box" pos="0.6 0.1 0.3">
      <joint type="free" limited="false" actuatorfrclimited="false"/>
      <geom size="0.02 0.02 0.02" type="box" mass="0.05" rgba="0.390084 0.778958 0.527843 1"/>
    </body>
  </worldbody>

  <contact>
    <exclude body1="base_link" body2="arm_seg1"/>
    <exclude body1="gripper1" body2="gripper2"/>
  </contact>

  <actuator>
    <general name="shoulder_rot" class="a1" joint="arm_joint1" ctrlrange="-2.8798 2.8798" forcerange="-40 40"/>
    <general name="shoulder_up" class="a1" joint="arm_joint2" ctrlrange="0 3.1415" forcerange="-40 40" gainprm="1500" biasprm="0 -1500 -150"/>
    <general name="elbow" class="a1" joint="arm_joint3" ctrlrange="-3.3161 0" forcerange="-27 27"/>
    <general name="wrist_rot" class="a1" joint="arm_joint4" ctrlrange="-2.8798 2.8798" forcerange="-7 7"/>
    <general name="wrist_swing" class="a1" joint="arm_joint5" ctrlrange="-1.6581 1.6581" forcerange="-7 7"/>
    <general name="gripper_rot" class="a1" joint="arm_joint6" ctrlrange="-2.8798 2.8798" forcerange="-7 7" gainprm="1500" biasprm="0 -1500 -150"/>
    <general name="gripper1" class="a1" joint="gripper1_axis" ctrlrange="0 0.03" forcerange="-200 200"/>
    <general name="gripper2" class="a1" joint="gripper2_axis" ctrlrange="0 0.03" forcerange="-200 200"/>
  </actuator>
</mujoco>
